2025-05-15 04:57:28 | ERROR | stderr | Loading safetensors checkpoint shards:   0% Completed | 0/4 [00:00<?, ?it/s]
2025-05-15 04:57:28 | ERROR | stderr | 
2025-05-15 04:57:32 | ERROR | stderr | Loading safetensors checkpoint shards:  25% Completed | 1/4 [00:03<00:11,  3.98s/it]
2025-05-15 04:57:32 | ERROR | stderr | 
2025-05-15 04:57:36 | ERROR | stderr | Loading safetensors checkpoint shards:  50% Completed | 2/4 [00:08<00:08,  4.02s/it]
2025-05-15 04:57:36 | ERROR | stderr | 
2025-05-15 04:57:40 | ERROR | stderr | Loading safetensors checkpoint shards:  75% Completed | 3/4 [00:11<00:03,  3.85s/it]
2025-05-15 04:57:40 | ERROR | stderr | 
2025-05-15 04:57:44 | ERROR | stderr | Loading safetensors checkpoint shards: 100% Completed | 4/4 [00:15<00:00,  3.95s/it]
2025-05-15 04:57:44 | ERROR | stderr | 
2025-05-15 04:57:44 | ERROR | stderr | Loading safetensors checkpoint shards: 100% Completed | 4/4 [00:15<00:00,  3.95s/it]
2025-05-15 04:57:44 | ERROR | stderr | 
2025-05-15 04:57:44 | ERROR | stderr | 
2025-05-15 04:58:02 | INFO | model_worker | Loading the model ['Qwen2.5-7B-Instruct'] on worker 92b5460c, worker type: vLLM worker...
2025-05-15 04:58:02 | INFO | model_worker | Register to controller
2025-05-15 04:58:02 | ERROR | stderr | [rank0]: Traceback (most recent call last):
2025-05-15 04:58:02 | ERROR | stderr | [rank0]:   File "/root/miniconda3/envs/open_reasoner/lib/python3.10/site-packages/urllib3/connection.py", line 198, in _new_conn
2025-05-15 04:58:02 | ERROR | stderr | [rank0]:     sock = connection.create_connection(
2025-05-15 04:58:02 | ERROR | stderr | [rank0]:   File "/root/miniconda3/envs/open_reasoner/lib/python3.10/site-packages/urllib3/util/connection.py", line 85, in create_connection
2025-05-15 04:58:02 | ERROR | stderr | [rank0]:     raise err
2025-05-15 04:58:02 | ERROR | stderr | [rank0]:   File "/root/miniconda3/envs/open_reasoner/lib/python3.10/site-packages/urllib3/util/connection.py", line 73, in create_connection
2025-05-15 04:58:02 | ERROR | stderr | [rank0]:     sock.connect(sa)
2025-05-15 04:58:02 | ERROR | stderr | [rank0]: ConnectionRefusedError: [Errno 111] Connection refused
2025-05-15 04:58:02 | ERROR | stderr | 
2025-05-15 04:58:02 | ERROR | stderr | [rank0]: The above exception was the direct cause of the following exception:
2025-05-15 04:58:02 | ERROR | stderr | 
2025-05-15 04:58:02 | ERROR | stderr | [rank0]: Traceback (most recent call last):
2025-05-15 04:58:02 | ERROR | stderr | [rank0]:   File "/root/miniconda3/envs/open_reasoner/lib/python3.10/site-packages/urllib3/connectionpool.py", line 787, in urlopen
2025-05-15 04:58:02 | ERROR | stderr | [rank0]:     response = self._make_request(
2025-05-15 04:58:02 | ERROR | stderr | [rank0]:   File "/root/miniconda3/envs/open_reasoner/lib/python3.10/site-packages/urllib3/connectionpool.py", line 493, in _make_request
2025-05-15 04:58:02 | ERROR | stderr | [rank0]:     conn.request(
2025-05-15 04:58:02 | ERROR | stderr | [rank0]:   File "/root/miniconda3/envs/open_reasoner/lib/python3.10/site-packages/urllib3/connection.py", line 445, in request
2025-05-15 04:58:02 | ERROR | stderr | [rank0]:     self.endheaders()
2025-05-15 04:58:02 | ERROR | stderr | [rank0]:   File "/root/miniconda3/envs/open_reasoner/lib/python3.10/http/client.py", line 1278, in endheaders
2025-05-15 04:58:02 | ERROR | stderr | [rank0]:     self._send_output(message_body, encode_chunked=encode_chunked)
2025-05-15 04:58:02 | ERROR | stderr | [rank0]:   File "/root/miniconda3/envs/open_reasoner/lib/python3.10/http/client.py", line 1038, in _send_output
2025-05-15 04:58:02 | ERROR | stderr | [rank0]:     self.send(msg)
2025-05-15 04:58:02 | ERROR | stderr | [rank0]:   File "/root/miniconda3/envs/open_reasoner/lib/python3.10/http/client.py", line 976, in send
2025-05-15 04:58:02 | ERROR | stderr | [rank0]:     self.connect()
2025-05-15 04:58:02 | ERROR | stderr | [rank0]:   File "/root/miniconda3/envs/open_reasoner/lib/python3.10/site-packages/urllib3/connection.py", line 276, in connect
2025-05-15 04:58:02 | ERROR | stderr | [rank0]:     self.sock = self._new_conn()
2025-05-15 04:58:02 | ERROR | stderr | [rank0]:   File "/root/miniconda3/envs/open_reasoner/lib/python3.10/site-packages/urllib3/connection.py", line 213, in _new_conn
2025-05-15 04:58:02 | ERROR | stderr | [rank0]:     raise NewConnectionError(
2025-05-15 04:58:02 | ERROR | stderr | [rank0]: urllib3.exceptions.NewConnectionError: <urllib3.connection.HTTPConnection object at 0x7f0f087c6f80>: Failed to establish a new connection: [Errno 111] Connection refused
2025-05-15 04:58:02 | ERROR | stderr | 
2025-05-15 04:58:02 | ERROR | stderr | [rank0]: The above exception was the direct cause of the following exception:
2025-05-15 04:58:02 | ERROR | stderr | 
2025-05-15 04:58:02 | ERROR | stderr | [rank0]: Traceback (most recent call last):
2025-05-15 04:58:02 | ERROR | stderr | [rank0]:   File "/root/miniconda3/envs/open_reasoner/lib/python3.10/site-packages/requests/adapters.py", line 667, in send
2025-05-15 04:58:02 | ERROR | stderr | [rank0]:     resp = conn.urlopen(
2025-05-15 04:58:02 | ERROR | stderr | [rank0]:   File "/root/miniconda3/envs/open_reasoner/lib/python3.10/site-packages/urllib3/connectionpool.py", line 841, in urlopen
2025-05-15 04:58:02 | ERROR | stderr | [rank0]:     retries = retries.increment(
2025-05-15 04:58:02 | ERROR | stderr | [rank0]:   File "/root/miniconda3/envs/open_reasoner/lib/python3.10/site-packages/urllib3/util/retry.py", line 519, in increment
2025-05-15 04:58:02 | ERROR | stderr | [rank0]:     raise MaxRetryError(_pool, url, reason) from reason  # type: ignore[arg-type]
2025-05-15 04:58:02 | ERROR | stderr | [rank0]: urllib3.exceptions.MaxRetryError: HTTPConnectionPool(host='0.0.0.0', port=28777): Max retries exceeded with url: /register_worker (Caused by NewConnectionError('<urllib3.connection.HTTPConnection object at 0x7f0f087c6f80>: Failed to establish a new connection: [Errno 111] Connection refused'))
2025-05-15 04:58:02 | ERROR | stderr | 
2025-05-15 04:58:02 | ERROR | stderr | [rank0]: During handling of the above exception, another exception occurred:
2025-05-15 04:58:02 | ERROR | stderr | 
2025-05-15 04:58:02 | ERROR | stderr | [rank0]: Traceback (most recent call last):
2025-05-15 04:58:02 | ERROR | stderr | [rank0]:   File "/root/miniconda3/envs/open_reasoner/lib/python3.10/runpy.py", line 196, in _run_module_as_main
2025-05-15 04:58:02 | ERROR | stderr | [rank0]:     return _run_code(code, main_globals, None,
2025-05-15 04:58:02 | ERROR | stderr | [rank0]:   File "/root/miniconda3/envs/open_reasoner/lib/python3.10/runpy.py", line 86, in _run_code
2025-05-15 04:58:02 | ERROR | stderr | [rank0]:     exec(code, run_globals)
2025-05-15 04:58:02 | ERROR | stderr | [rank0]:   File "/fs-computility/mabasic/fanyuchen/openr/reason/llm_service/workers/vllm_worker.py", line 270, in <module>
2025-05-15 04:58:02 | ERROR | stderr | [rank0]:     worker = VLLMWorker(
2025-05-15 04:58:02 | ERROR | stderr | [rank0]:   File "/fs-computility/mabasic/fanyuchen/openr/reason/llm_service/workers/vllm_worker.py", line 61, in __init__
2025-05-15 04:58:02 | ERROR | stderr | [rank0]:     self.init_heart_beat()
2025-05-15 04:58:02 | ERROR | stderr | [rank0]:   File "/fs-computility/mabasic/fanyuchen/openr/reason/llm_service/workers/base_model_worker.py", line 79, in init_heart_beat
2025-05-15 04:58:02 | ERROR | stderr | [rank0]:     self.register_to_controller()
2025-05-15 04:58:02 | ERROR | stderr | [rank0]:   File "/fs-computility/mabasic/fanyuchen/openr/reason/llm_service/workers/base_model_worker.py", line 96, in register_to_controller
2025-05-15 04:58:02 | ERROR | stderr | [rank0]:     r = requests.post(url, json=data)
2025-05-15 04:58:02 | ERROR | stderr | [rank0]:   File "/root/miniconda3/envs/open_reasoner/lib/python3.10/site-packages/requests/api.py", line 115, in post
2025-05-15 04:58:02 | ERROR | stderr | [rank0]:     return request("post", url, data=data, json=json, **kwargs)
2025-05-15 04:58:02 | ERROR | stderr | [rank0]:   File "/root/miniconda3/envs/open_reasoner/lib/python3.10/site-packages/requests/api.py", line 59, in request
2025-05-15 04:58:02 | ERROR | stderr | [rank0]:     return session.request(method=method, url=url, **kwargs)
2025-05-15 04:58:02 | ERROR | stderr | [rank0]:   File "/root/miniconda3/envs/open_reasoner/lib/python3.10/site-packages/requests/sessions.py", line 589, in request
2025-05-15 04:58:02 | ERROR | stderr | [rank0]:     resp = self.send(prep, **send_kwargs)
2025-05-15 04:58:02 | ERROR | stderr | [rank0]:   File "/root/miniconda3/envs/open_reasoner/lib/python3.10/site-packages/requests/sessions.py", line 703, in send
2025-05-15 04:58:02 | ERROR | stderr | [rank0]:     r = adapter.send(request, **kwargs)
2025-05-15 04:58:02 | ERROR | stderr | [rank0]:   File "/root/miniconda3/envs/open_reasoner/lib/python3.10/site-packages/requests/adapters.py", line 700, in send
2025-05-15 04:58:02 | ERROR | stderr | [rank0]:     raise ConnectionError(e, request=request)
2025-05-15 04:58:02 | ERROR | stderr | [rank0]: requests.exceptions.ConnectionError: HTTPConnectionPool(host='0.0.0.0', port=28777): Max retries exceeded with url: /register_worker (Caused by NewConnectionError('<urllib3.connection.HTTPConnection object at 0x7f0f087c6f80>: Failed to establish a new connection: [Errno 111] Connection refused'))
